Workbook

Sheet 0_Create_Guide
A1: How to create this Excel KPI sheet (Signature Flatbreads)
A3: Step | B3: What to do | C3: Sheet
A4: 1 | B4: Create a new Excel workbook and rename sheets as shown in column C | C4: —
A5: 2 | B5: On Parameters sheet: enter Weights, Year-1 Targets, Lines, Bonus opportunities | C5: 1_Parameters
A6: 3 | B6: On Actuals sheet: create one column per line (P1, T1, T2, L8, L9) and yellow input rows | C6: 2_Actuals
A7: 4 | B7: On Scorecard sheet: add formulas for Actual → Score% → Weighted for each KPI | C7: 3_Scorecard
A8: 5 | B8: On Bonus sheet: AVERAGE line scores, apply gatekeepers, calculate role payouts | C8: 4_Bonus
A9: 6 | B9: Protect green (formula) cells; leave yellow (input) cells editable | C9: All sheets
A10: 7 | B10: Each month: only change yellow Actuals + Month; scores update automatically | C10: 2_Actuals
A12: Sheet list you need
A13: Sheet name | B13: Purpose
A14: 1_Parameters | B14: All fixed settings: weights, targets, lines, bonus £, rules
A15: 2_Actuals | B15: Monthly typed data (yellow) for each machine line
A16: 3_Scorecard | B16: Calculations: Actual vs Target → Score → Weighted → Line total
A17: 4_Bonus | B17: Plant average + safety rules + money payout
A20: Colour rules when you build the sheet
A21: Yellow | B21: INPUT parameter / actual — user types here
A22: Blue | B22: PARAMETER (target/weight) — change only if scheme changes
A23: Green | B23: FORMULA — never type over these

Sheet 1_Parameters
A1: PARAMETERS — set these once (ask manager before changing)
A3: A) Production lines (columns on Actuals sheet)
A4: Line code | B4: Machine name | C4: Family | D4: Include in bonus? (Yes/No)
A5: P1 | B5: Pancake machinery | C5: Pancake | D5: Yes
A6: T1 | B6: Tortilla wrap machinery | C6: Tortilla | D6: Yes
A7: T2 | B7: Tortilla wrap machinery | C7: Tortilla | D7: Yes
A8: L8 | B8: Line L8 | C8: L-series | D8: Yes
A9: L9 | B9: Line L9 | C9: L-series | D9: Yes
A11: B) KPI parameters (Weight + Targets)
A12: KPI ID | B12: KPI name | C12: Weight | D12: Direction | E12: Year1 Target | F12: Year2 Target | G12: Year3 Target | H12: Unit | I12: Score rule
A13: OEE | B13: Overall Equipment Effectiveness | C13: 0.2 | D13: higher_better | E13: 82 | F13: 82 | G13: 82 | H13: % | I13: MIN(100, Actual/Target*100)
A14: BF | B14: Breakdown Frequency | C14: 0.1 | D14: lower_better | E14: 15 | F14: 10 | G14: 10 | H14: count/line/month | I14: IF(Actual=0,100,MIN(100,Target/Actual*100))
A15: BH | B15: Breakdown Hours | C15: 0.15 | D15: lower_better | E15: 20 | F15: 12 | G15: 5 | H15: hours/line/month | I15: IF(Actual=0,100,MIN(100,Target/Actual*100))
A16: PM | B16: PM Compliance | C16: 0.2 | D16: higher_better | E16: 98 | F16: 98 | G16: 98 | H16: % | I16: MIN(100, Actual/Target*100)
A17: MTTR | B17: Mean Time To Repair | C17: 0.15 | D17: lower_better | E17: 2.5 | F17: 2 | G17: 1.5 | H17: hours | I17: IF(Actual=0,100,MIN(100,Target/Actual*100))
A18: MTBF | B18: Mean Time Between Failures | C18: 0.1 | D18: higher_better | E18: 150 | F18: 500 | G18: 1000 | H18: hours | I18: MIN(100, Actual/Target*100)
A19: SAFE | B19: Safety (LTI) | C19: 0.1 | D19: zero_lti | E19: 0 | F19: 0 | G19: 0 | H19: LTI count | I19: IF(LTI=0,100,0)
A21: Weight total (must = 100%) | B21: =SUM(C13:C19) | C21: =IF(ABS(B21-1)<0.001,"OK — weights add to 100%","ERROR — fix weights")
A23: C) Gatekeeper / bonus rule parameters
A24: Rule ID | B24: Parameter name | C24: Value | D24: Meaning
A25: CAP_KPI | B25: Max individual KPI score % | C25: 100 | D25: No KPI score above 100%
A26: CAP_TOTAL | B26: Max overall score % | C26: 100 | D26: Overall bonus score capped at 100%
A27: LTI_FACTOR | B27: If LTI > 0, multiply bonus by | C27: 0.5 | D27: Lost Time Injury halves the bonus
A28: RED_AUDIT | B28: If red audit, multiply bonus by | C28: 0.5 | D28: Red audit halves the bonus
A29: MAJOR_SAFETY | B29: Major safety violation → bonus % | C29: 0 | D29: Bonus stops
A30: MAJOR_EPW | B30: Major EPW → bonus % | C30: 0 | D30: Bonus stops
A31: DISHONEST | B31: Dishonest reporting → bonus % | C31: 0 | D31: Bonus stops
A32: GREEN_AUDIT | B32: Green audit extra reward? | C32: YES | D32: Confirm £ amount with manager
A35: D) Monthly bonus opportunity parameters (£)
A36: Shift | B36: Role | C36: Opportunity £
A37: Day | B37: Head of department | C37: 1235
A38: Day | B38: Managers | C38: 918
A39: Day | B39: Team leaders | C39: 810
A40: Day | B40: Multi-skilled | C40: 486
A41: Day | B41: Mech / Elec / Maint eng / Control / Electrician | C41: 324
A42: Day | B42: Handyman / Electrician mate | C42: 243
A43: Night | B43: Team leaders | C43: 1020
A44: Night | B44: Multi-skilled | C44: 900
A45: Night | B45: Mech / Elec / Maint eng / Control / Electrician | C45: 540
A46: Night | B46: Handyman / Electrician mate | C46: 360
...

Sheet 2_Actuals
A1: ACTUALS — create one column per line; type only yellow cells each month
A2: Month (YYYY-MM) | B2: 2026-07 | C2: ← change this every month
A4: Parameter (what to enter) | B4: Where to get it | C4: P1 | D4: T1 | E4: T2 | F4: L8 | G4: L9
A5: Line name (auto from Parameters) | B5: Parameters sheet | C5: =1_Parameters!B5 | D5: =1_Parameters!B6 | E5: =1_Parameters!B7 | F5: =1_Parameters!B8 | G5: =1_Parameters!B9
A6: Planned production hours | B6: Production plan / Excel | C6: 0 | D6: 0 | E6: 0 | F6: 0 | G6: 0
A7: Actual operating hours | B7: Line log / Excel | C7: 0 | D7: 0 | E7: 0 | F7: 0 | G7: 0
A8: Ideal rate (units per hour) | B8: Engineering standard | C8: 0 | D8: 0 | E8: 0 | F8: 0 | G8: 0
A9: Actual output units | B9: Production count | C9: 0 | D9: 0 | E9: 0 | F9: 0 | G9: 0
A10: Good units (quality OK) | B10: Quality / scrap log | C10: 0 | D10: 0 | E10: 0 | F10: 0 | G10: 0
A11: Breakdown count | B11: Teams + Maintainer | C11: 0 | D11: 0 | E11: 0 | F11: 0 | G11: 0
A12: Breakdown hours | B12: Excel downtime start→end | C12: 0 | D12: 0 | E12: 0 | F12: 0 | G12: 0
A13: Planned PM jobs | B13: Maintainer | C13: 0 | D13: 0 | E13: 0 | F13: 0 | G13: 0
A14: Completed PM on time | B14: Maintainer completion date | C14: 0 | D14: 0 | E14: 0 | F14: 0 | G14: 0
A15: Operational hours (for MTBF) | B15: Excel runtime | C15: 0 | D15: 0 | E15: 0 | F15: 0 | G15: 0
A16: LTI count | B16: H&S | C16: 0 | D16: 0 | E16: 0 | F16: 0 | G16: 0
A17: Major safety violation (0 or 1) | B17: H&S | C17: 0 | D17: 0 | E17: 0 | F17: 0 | G17: 0
... A19: Dishonest reporting (0 or 1) | B19: Management | C19: 0 | D19: 0 | E19: 0 | F19: 0 | G19: 0
A20: Audit result | B20: Audit team (green/amber/red)
A22: How to create this Actuals layout yourself
A23: 1. Row 1–2: title + Month parameter
A24: 2. Row 4: headers = Line codes from Parameters (P1, T1, T2, L8, L9)
A25: 3. Rows 6–20: one parameter per row (list above) — these are your INPUT PARAMETERS
A26: 4. Paint input cells yellow; leave formulas green on Scorecard
A27: 5. Add Data Validation dropdowns for Audit (green/amber/red) and 0/1 flags
A28: 6. Optional: start from sample file Excel_KPI_Calculator.xlsx which already has formulas filled

Sheet 3_Scorecard
A1: SCORECARD — formulas use Parameters (weights/targets) + Actuals
A2: Month | B2: =2_Actuals!B2
C3: P1 | G3: T1 | K3: T2 | O3: L8 | S3: L9
A4: KPI | B4: Weight | C4: Actual | D4: Target | E4: Score % | F4: Weighted | G4: Actual | H4: Target | I4: Score % | J4: Weighted | K4: Actual | L4: Target | M4: Score % | N4: Weighted | O4: Actual | P4: Target | Q4: Score % | R4: Weighted | S4: Actual | T4: Target | U4: Score % | V4: Weighted
A5: OEE % | B5: ='1_Parameters'!C13 | C5: =IF(2_Actuals!C6=0,0,((2_Actuals!C7/2_Actuals!C6)*((2_Actuals!C9/2_Actuals!C7)/2_Actuals!C8)*(2_Actuals!C10/2_Actuals!C9))*100) | D5: ='1_Parameters'!E13 | E5: =IF(D5=0,0,MIN(1_Parameters!$C$25,C5/D5*100)) | F5: =E5*$B5 | G5: =IF(2_Actuals!D6=0,0,((2_Actuals!D7/2_Actuals!D6)*((2_Actuals!D9/2_Actuals!D7)/2_Actuals!D8)*(2_Actuals!D10/2_Actuals!D9))*100) | H5: ='1_Parameters'!E13 | I5: =IF(H5=0,0,MIN(1_Parameters!$C$25,G5/H5*100)) | J5: =I5*$B5 | K5: =IF(2_Actuals!E6=0,0,((2_Actuals!E7/2_Actuals!E6)*((2_Actuals!E9/2_Actuals!E7)/2_Actuals!E8)*(2_Actuals!E10/2_Actuals!E9))*100) | L5: ='1_Parameters'!E13 | M5: =IF(L5=0,0,MIN(1_Parameters!$C$25,K5/L5*100)) | N5: =M5*$B5 | O5: =IF(2_Actuals!F6=0,0,((2_Actuals!F7/2_Actuals!F6)*((2_Actuals!F9/2_Actuals!F7)/2_Actuals!F8)*(2_Actuals!F10/2_Actuals!F9))*100) | P5: ='1_Parameters'!E13 | Q5: =IF(P5=0,0,MIN(1_Parameters!$C$25,O5/P5*100)) | R5: =Q5*$B5 | S5: =IF(2_Actuals!G6=0,0,((2_Actuals!G7/2_Actuals!G6)*((2_Actuals!G9/2_Actuals!G7)/2_Actuals!G8)*(2_Actuals!G10/2_Actuals!G9))*100) | T5: ='1_Parameters'!E13 | U5: =IF(T5=0,0,MIN(1_Parameters!$C$25,S5/T5*100)) | V5: =U5*$B5
A6: Breakdown Frequency | B6: ='1_Parameters'!C14 | C6: =2_Actuals!C11 | D6: ='1_Parameters'!E14 | E6: =IF(C6=0,100,MIN(1_Parameters!$C$25,D6/C6*100)) | F6: =E6*$B6 | G6: =2_Actuals!D11 | H6: ='1_Parameters'!E14 | I6: =IF(G6=0,100,MIN(1_Parameters!$C$25,H6/G6*100)) | J6: =I6*$B6 | K6: =2_Actuals!E11 | L6: ='1_Parameters'!E14 | M6: =IF(K6=0,100,MIN(1_Parameters!$C$25,L6/K6*100)) | N6: =M6*$B6 | O6: =2_Actuals!F11 | P6: ='1_Parameters'!E14 | Q6: =IF(O6=0,100,MIN(1_Parameters!$C$25,P6/O6*100)) | R6: =Q6*$B6 | S6: =2_Actuals!G11 | T6: ='1_Parameters'!E14 | U6: =IF(S6=0,100,MIN(1_Parameters!$C$25,T6/S6*100)) | V6: =U6*$B6
A7: Breakdown Hours | B7: ='1_Parameters'!C15 | C7: =2_Actuals!C12 | D7: ='1_Parameters'!E15 | E7: =IF(C7=0,100,MIN(1_Parameters!$C$25,D7/C7*100)) | F7: =E7*$B7 | G7: =2_Actuals!D12 | H7: ='1_Parameters'!E15 | I7: =IF(G7=0,100,MIN(1_Parameters!$C$25,H7/G7*100)) | J7: =I7*$B7 | K7: =2_Actuals!E12 | L7: ='1_Parameters'!E15 | M7: =IF(K7=0,100,MIN(1_Parameters!$C$25,L7/K7*100)) | N7: =M7*$B7 | O7: =2_Actuals!F12 | P7: ='1_Parameters'!E15 | Q7: =IF(O7=0,100,MIN(1_Parameters!$C$25,P7/O7*100)) | R7: =Q7*$B7 | S7: =2_Actuals!G12 | T7: ='1_Parameters'!E15 | U7: =IF(S7=0,100,MIN(1_Parameters!$C$25,T7/S7*100)) | V7: =U7*$B7
A8: PM Compliance % | B8: ='1_Parameters'!C16 | C8: =IF(2_Actuals!C13=0,0,2_Actuals!C14/2_Actuals!C13*100) | D8: ='1_Parameters'!E16 | E8: =IF(D8=0,0,MIN(1_Parameters!$C$25,C8/D8*100)) | F8: =E8*$B8 | G8: =IF(2_Actuals!D13=0,0,2_Actuals!D14/2_Actuals!D13*100) | H8: ='1_Parameters'!E16 | I8: =IF(H8=0,0,MIN(1_Parameters!$C$25,G8/H8*100)) | J8: =I8*$B8 | K8: =IF(2_Actuals!E13=0,0,2_Actuals!E14/2_Actuals!E13*100) | L8: ='1_Parameters'!E16 | M8: =IF(L8=0,0,MIN(1_Parameters!$C$25,K8/L8*100)) | N8: =M8*$B8 | O8: =IF(2_Actuals!F13=0,0,2_Actuals!F14/2_Actuals!F13*100) | P8: ='1_Parameters'!E16 | Q8: =IF(P8=0,0,MIN(1_Parameters!$C$25,O8/P8*100)) | R8: =Q8*$B8 | S8: =IF(2_Actuals!G13=0,0,2_Actuals!G14/2_Actuals!G13*100) | T8: ='1_Parameters'!E16 | U8: =IF(T8=0,0,MIN(1_Parameters!$C$25,S8/T8*100)) | V8: =U8*$B8
A9: MTTR hours | B9: ='1_Parameters'!C17 | C9: =IF(2_Actuals!C11=0,0,2_Actuals!C12/2_Actuals!C11) | D9: ='1_Parameters'!E17 | E9: =IF(C9=0,100,MIN(1_Parameters!$C$25,D9/C9*100)) | F9: =E9*$B9 | G9: =IF(2_Actuals!D11=0,0,2_Actuals!D12/2_Actuals!D11) | H9: ='1_Parameters'!E17 | I9: =IF(G9=0,100,MIN(1_Parameters!$C$25,H9/G9*100)) | J9: =I9*$B9 | K9: =IF(2_Actuals!E11=0,0,2_Actuals!E12/2_Actuals!E11) | L9: ='1_Parameters'!E17 | M9: =IF(K9=0,100,MIN(1_Parameters!$C$25,L9/K9*100)) | N9: =M9*$B9 | O9: =IF(2_Actuals!F11=0,0,2_Actuals!F12/2_Actuals!F11) | P9: ='1_Parameters'!E17 | Q9: =IF(O9=0,100,MIN(1_Parameters!$C$25,P9/O9*100)) | R9: =Q9*$B9 | S9: =IF(2_Actuals!G11=0,0,2_Actuals!G12/2_Actuals!G11) | T9: ='1_Parameters'!E17 | U9: =IF(S9=0,100,MIN(1_Parameters!$C$25,T9/S9*100)) | V9: =U9*$B9
A10: MTBF hours | B10: ='1_Parameters'!C18 | C10: =IF(2_Actuals!C11=0,2_Actuals!C15,2_Actuals!C15/2_Actuals!C11) | D10: ='1_Parameters'!E18 | E10: =IF(D10=0,0,MIN(1_Parameters!$C$25,C10/D10*100)) | F10: =E10*$B10 | G10: =IF(2_Actuals!D11=0,2_Actuals!D15,2_Actuals!D15/2_Actuals!D11) | H10: ='1_Parameters'!E18 | I10: =IF(H10=0,0,MIN(1_Parameters!$C$25,G10/H10*100)) | J10: =I10*$B10 | K10: =IF(2_Actuals!E11=0,2_Actuals!E15,2_Actuals!E15/2_Actuals!E11) | L10: ='1_Parameters'!E18 | M10: =IF(L10=0,0,MIN(1_Parameters!$C$25,K10/L10*100)) | N10: =M10*$B10 | O10: =IF(2_Actuals!F11=0,2_Actuals!F15,2_Actuals!F15/2_Actuals!F11) | P10: ='1_Parameters'!E18 | Q10: =IF(P10=0,0,MIN(1_Parameters!$C$25,O10/P10*100)) | R10: =Q10*$B10 | S10: =IF(2_Actuals!G11=0,2_Actuals!G15,2_Actuals!G15/2_Actuals!G11) | T10: ='1_Parameters'!E18 | U10: =IF(T10=0,0,MIN(1_Parameters!$C$25,S10/T10*100)) | V10: =U10*$B10
A11: Safety | B11: ='1_Parameters'!C19 | C11: =2_Actuals!C16 | D11: ='1_Parameters'!E19 | E11: =IF(C11=0,100,0) | F11: =E11*$B11 | G11: =2_Actuals!D16 | H11: ='1_Parameters'!E19 | I11: =IF(G11=0,100,0) | J11: =I11*$B11 | K11: =2_Actuals!E16 | L11: ='1_Parameters'!E19 | M11: =IF(K11=0,100,0) | N11: =M11*$B11 | O11: =2_Actuals!F16 | P11: ='1_Parameters'!E19 | Q11: =IF(O11=0,100,0) | R11: =Q11*$B11 | S11: =2_Actuals!G16 | T11: ='1_Parameters'!E19 | U11: =IF(S11=0,100,0) | V11: =U11*$B11
A12: LINE KPI SCORE % | F12: =MIN(1_Parameters!$C$26,SUM(F5:F11)) | J12: =MIN(1_Parameters!$C$26,SUM(J5:J11)) | N12: =MIN(1_Parameters!$C$26,SUM(N5:N11)) | R12: =MIN(1_Parameters!$C$26,SUM(R5:R11)) | V12: =MIN(1_Parameters!$C$26,SUM(V5:V11))
A14: Parameter links used on this sheet
A15: Weights ← 1_Parameters!C13:C19
A16: Year1 Targets ← 1_Parameters!E13:E19
A17: Score cap ← 1_Parameters!C25 (usually 100)
A18: Total cap ← 1_Parameters!C26 (usually 100)
A19: If Actuals are still 0, scores may look odd — enter real monthly numbers on 2_Actuals first.

Sheet 4_Bonus
A1: BONUS — plant score, gatekeepers, payouts (driven by Parameters)
A3: Line | B3: KPI Score %
A4: =1_Parameters!A5&" — "&1_Parameters!B5 | B4: =3_Scorecard!F12
A5: =1_Parameters!A6&" — "&1_Parameters!B6 | B5: =3_Scorecard!J12
A6: =1_Parameters!A7&" — "&1_Parameters!B7 | B6: =3_Scorecard!N12
A7: =1_Parameters!A8&" — "&1_Parameters!B8 | B7: =3_Scorecard!R12
A8: =1_Parameters!A9&" — "&1_Parameters!B9 | B8: =3_Scorecard!V12
A9: Plant score % (AVERAGE) | B9: =AVERAGE(B4:B8)
A11: Gatekeeper checks
A12: Total LTI | B12: =SUM(2_Actuals!C16:G16)
A13: Major safety? | B13: =IF(SUM(2_Actuals!C17:G17)>0,"YES","NO")
A14: Major EPW? | B14: =IF(SUM(2_Actuals!C18:G18)>0,"YES","NO")
A15: Dishonest? | B15: =IF(SUM(2_Actuals!C19:G19)>0,"YES","NO")
A16: Red audit? | B16: =IF(COUNTIF(2_Actuals!C20:G20,"red")>0,"YES","NO")
A18: FINAL BONUS SCORE % | B18: =IF(OR(B13="YES",B14="YES",B15="YES"),0,IF(B12>0,B9*1_Parameters!C27,B9)*IF(B16="YES",1_Parameters!C28,1))
A20: Payouts = Opportunity (Parameters) × Final score %
A21: Shift | B21: Role | C21: Opportunity £ | D21: Final % | E21: Payout £
A22: =1_Parameters!A37 | B22: =1_Parameters!B37 | C22: =1_Parameters!C37 | D22: =$B$18 | E22: =C22*D22/100
A23: =1_Parameters!A38 | B23: =1_Parameters!B38 | C23: =1_Parameters!C38 | D23: =$B$18 | E23: =C23*D23/100
A24: =1_Parameters!A39 | B24: =1_Parameters!B39 | C24: =1_Parameters!C39 | D24: =$B$18 | E24: =C24*D24/100
A25: =1_Parameters!A40 | B25: =1_Parameters!B40 | C25: =1_Parameters!C40 | D25: =$B$18 | E25: =C25*D25/100
A26: =1_Parameters!A41 | B26: =1_Parameters!B41 | C26: =1_Parameters!C41 | D26: =$B$18 | E26: =C26*D26/100
A27: =1_Parameters!A42 | B27: =1_Parameters!B42 | C27: =1_Parameters!C42 | D27: =$B$18 | E27: =C27*D27/100
A28: =1_Parameters!A43 | B28: =1_Parameters!B43 | C28: =1_Parameters!C43 | D28: =$B$18 | E28: =C28*D28/100
A29: =1_Parameters!A44 | B29: =1_Parameters!B44 | C29: =1_Parameters!C44 | D29: =$B$18 | E29: =C29*D29/100
A30: =1_Parameters!A45 | B30: =1_Parameters!B45 | C30: =1_Parameters!C45 | D30: =$B$18 | E30: =C30*D30/100
A31: =1_Parameters!A46 | B31: =1_Parameters!B46 | C31: =1_Parameters!C46 | D31: =$B$18 | E31: =C31*D31/100
A32: =1_Parameters!A47 | B32: =1_Parameters!B47 | C32: =1_Parameters!C47 | D32: =$B$18 | E32: =C32*D32/100

Sheet Parameter_List
A1: Complete parameter list — what each field means
A3: Group | B3: Parameter | C3: Example | D3: Type | E3: Who sets it? | F3: Used for
A4: Line | B4: Line code | C4: P1 | D4: Text | E4: Manager | F4: Identify machine column
A5: Line | B5: Machine name | C5: Pancake machinery | D5: Text | E5: Manager | F5: Reports / labels
A6: KPI | B6: Weight | C6: 20% | D6: Number 0–1 | E6: Scheme V2 | F6: Weighted contribution
A7: KPI | B7: Year1 Target OEE | C7: 82 | D7: % | E7: Scheme V2 | F7: OEE score
A8: KPI | B8: Year1 Target BF | C8: 15 | D8: Count | E8: Scheme V2 | F8: Breakdown frequency score
A9: KPI | B9: Year1 Target BH | C9: 20 | D9: Hours | E9: Scheme V2 | F9: Breakdown hours score
A10: KPI | B10: Year1 Target PM | C10: 98 | D10: % | E10: Scheme V2 | F10: PM compliance score
A11: KPI | B11: Year1 Target MTTR | C11: 2.5 | D11: Hours | E11: Scheme V2 | F11: MTTR score
A12: KPI | B12: Year1 Target MTBF | C12: 150 | D12: Hours | E12: Scheme V2 | F12: MTBF score
A13: KPI | B13: Year1 Target Safety | C13: 0 | D13: LTI | E13: Scheme V2 | F13: Safety score
A14: Actual | B14: Planned production hours | C14: 480 | D14: Hours | E14: Data analyst / Production | F14: OEE availability
... A28: Rule | B28: Score cap | C28: 100 | D28: % | E28: Scheme V2 | F28: MIN() in formulas
